<?xml version="1.0"?>
    
    <robot name="inverted_pendulum">

       
 

        


         <!--COMMENT: Defining a macro to define the inertai element-->  <!--*(l_y*l_y+l_z*l_z) *(l_x*l_x+l_z*l_z) *(l_x*l_x+l_y*l_y)-->
         <!-- <xacro:macro name="box_inertia_element" params="l_x l_y l_z mass">
            <inertia ixx="${mass/12 * (l_y*l_y + l_z*l_z)}" ixy="0" ixz="0" 
                     iyy="${mass/12 * (l_x*l_x + l_z*l_z)}" iyz="0" izz="${mass/12 * (l_x*l_x + l_y*l_y)}" />
        </xacro:macro> -->


        <!--link definition-->
        <link name="link_world"></link> 

         <joint name="world_joint" type="fixed">
            <origin xyz="1 1 0.05" rpy="0.0 0.0 0.0"/>
            <parent link="link_world"/>
            <child link="link_ref"/>
        </joint>


        <link name="link_ref"> <!--reference link-->
            <inertial>
                <origin xyz="0 0 0" rpy="0 0 0" />
                <mass value="1.0" />
                <inertia ixx="0.1" ixy="0" ixz="0" iyy="0.1" iyz="0" izz="0.1" />
            </inertial>
            <visual>
                <origin xyz="0 0 0" rpy="0 0 0" />
                <geometry>
                    <box size="4 1 0.1" />
                </geometry>
            </visual>
            <collision>
                <origin xyz="0 0 0" rpy="0 0 0" />
                <geometry>
                    <box size="4 1 0.1" />
                </geometry>
            </collision>
        </link>

        <joint name="joint_ref_cart" type="prismatic">
            <origin xyz="0.0 0.0 0.05" rpy="0.0 0.0 0.0" />
            <parent link="link_ref" />
            <child link="link_cart" />
            <axis xyz="1 0 0" />
            <limit lower="-2" upper="2" effort="100" velocity="10" />
        </joint>

        <link name="link_cart">
            <inertial>
                <origin xyz="0 0 0.0125" rpy="0 0 0" />
                <mass value="1" />
                <inertia ixx="0.2" ixy="0" ixz="0" iyy="0.1" iyz="0" izz="0.2" />
            </inertial>
            <visual>
                <origin xyz="0 0 0.0125" rpy="0 0 0" />
                <geometry>
                    <box size="0.2 0.4 0.025" />
                </geometry>
                <material name="Blue">
                    <color rgba="0 0 1 0.4" />
                </material>
            </visual>
            <collision>
                <origin xyz="0 0 0.0125" rpy="0 0 0" />
                <geometry>
                    <box size="0.2 0.4 0.025" />
                </geometry>
            </collision>
        </link>

          <joint name="joint_cart_pendulum" type="revolute">
            <parent link="link_cart" />
            <child link="link_pendulum" />
            <origin xyz="0 0 0.025" rpy="0 0 0" />
            <axis xyz="0 1 0" />
            <limit lower="-1.57" upper="1.57" effort="100" velocity="10"/>
        </joint>
        
        <link name="link_pendulum">
            <inertial>
                <origin xyz="0 0 0.25" rpy="0 0 0" />
                <mass value="0.2" />
                <inertia ixx="0.05" ixy="0" ixz="0" iyy="0.1" iyz="0" izz="0.02" />
            </inertial>
            <visual>
                <origin xyz="0 0 0.25" rpy="0 0 0" /> 
                <geometry>
                    <box size="0.05 0.025 0.5" />
                </geometry>
                <material name="Gray">
                    <color rgba="0.33 0.33 0.33 0.4" />
                </material>
            </visual>
            <collision>
                <origin xyz="0 0 0.25" rpy="0 0 0" /> 
                <geometry>
                    <box size="0.05 0.025 0.5" />
                </geometry>
            </collision>
        </link> 
        

        <!--Joints defintion-->

        


      
        




    </robot>
